## 异常处理

Python的异常机制主要依赖`try`、`except`、`else`、`finally`、`raise`五个关键字，其中`try`关键字后缩进的代码块简称`try`块，它里面放置的是可能引发异常的代码；在`except`后对应的是异常类型和一个代码块，用于表明该`except` 块处理这种类型的代码块；在多个`except`块之后可以放一个`else`块，表明程序不出现异常时还要执行`else`块；最后还可以跟一个`finally`块，`finally`块用于回收在`try`块里打开的物理资源，异常机制会保证`finally`块总被执行；`raise`用于引发一个实际的异常，`raise`可以单独作为语句使用，引发一个具体的异常对象。



### 使用`try...except`捕获异常

Python提出了一个假设：**如果程序可以顺利完成，那就"一切正常"，把系统的业务实现代码放在`try`块中定义，把所有的异常处理逻辑放在`except`块中进行处理。**

```python
try:
    #业务实现代码
except (Error1,Error2,...) as e:
    alert 输入不合法
    goto retry
```

如果在执行`try`块里的业务逻辑代码时出现异常，系统自动生成一个异常对象，该异常对象被提交给Python解释器，这个过程被称为**引发异常**。

当Python解释器收到异常对象时，会寻找能处理该异常对象的`except`块，如果找到合适的`except`块，则把该异常对象交给该`except`块处理，这个过程被称为**捕获异常**。如果Python解释器找不到捕获异常的`except`块，则运行时环境终止，Python解释器也将退出。



Python解释器接收到异常对象后，会依次判断该异常对象是否是`except`块后的异常类或其子类的实例，如果是，Python解释器将调用该`except`块来处理该异常；否则，再次拿该异常对象和下一个`except`块里的异常类进行比较。

通常情况下，如果`try`块被执行一次，则`try`块后只有一个`except`块会被执行，不可能有多个`except`块被执行。除非在循环中使用了`continue`开始下一次循环，下一次循环又重新运行了`try`块，这才可能导致多个`except`块被执行。



在进行异常捕获时不仅应该把`Exception`类对应的`except`块放在最后，而且所有父类异常的`except`块都应该排在子类异常的`except`块的后面(即：**先处理小异常，再处理大异常**)。



### `try...except`语句工作流程：

1. 执行`try`子句(在关键字`try`和关键字`except`之间的语句)；
2. 如果没有异常发生，忽略`except`子句，`try`执行后结束；
3. 如果在执行`try`子句的过程中发生了异常，那么`try`子句余下的部分将被忽略。如果异常的类型和`except`之后的名称相符，那么对应的`except`子句将被执行。最后执行`try`语句之后的代码；
4. 如果一个异常没有与任何的`except`匹配，那么这个异常将会传递给上层的`try`中。



### 多异常捕获

在使用一个`except`块捕获多种类型的异常时，只要将多个异常类用括号括起来，中间用逗号隔开——其实就是构建多个异常类的元组。

```python
import sys
try:
    a = int(sys.argv[1])
    b = int(sys.argv[2])
    c = a / b
    print("您输入的两个数相除的结果是：", c )
except (IndexError, ValueError, ArithmeticError):
    print("程序发生了数组越界、数字格式异常、算术异常之一")
except:
    print("未知异常")
```

如果只有`except`关键字，并未指定具体要捕获的异常类型，这种省略异常类的`except`语句也是合法的，它表示可捕获所有类型的异常，一般会作为异常捕获的最后一个`except`块。



### 访问异常信息

如果要访问异常对象，只要在单个异常类或异常类元组(多异常捕获)之后使用`as`再加上异常变量。

```python
def foo():
    try:
        fis = open("a.txt");
    except Exception as e:
        # 访问异常的错误编号和详细信息
        print(e.args)
        # 访问异常的错误编号
        print(e.errno)
        # 访问异常的详细信息
        print(e.strerror)
foo()
```



### `else`块

当`try`块没有出现异常时，程序会执行`else`块。



### 使用`finally`回收资源

```python
try:
    #业务实现代码
    ...
except SubException1 as e:
    #异常处理块1
    ...
except SubException2 as e:
    #异常处理块2
    ...
...
else:
    #正常模块
finally:
    #资源回收块
    ...
```

在异常处理语法结构中，只有`try`块是必需的，如果没有`try` 块，则不能有后面的`except`块和`finally`块；`except`块和`finally`块都是可选的，但`except`块和`finally`块至少出现其中之一，也可以同时出现。



除非在`try`块、`except`块中调用了退出Python解释器的方法，否则不管在`try`块、`except`块中执行怎样的代码，出现怎样的情况，异常处理的`finally`块总会被执行。调用`sys.exit()`方法退出程序不能阻止`finally`块的执行，这是因为`sys.exit()`方法本身就是通过引发`SystemExit`异常来退出程序的。



Python程序在执行`try`块、`except`块时遇到了`return`或`raise`语句，这两条语句都会导致该方法立即结束，那么系统执行这两条语句并不会结束该方法，而是去寻找该异常处理流程中的`finally`块，如果没有找到`finally`块，程序立即执行`return`或`raise`语句，方法终止；如果找到`finally`块，系统立即开始执行`finally`块——只有当`finally`块执行完成后，系统才会再次跳回来执行`try`块、`except`块里的`return`或`raise`语句；如果在`finally`块里也使用了`return`或`raise`等导致方法中止的语句，系统将不会跳回去执行`try`块、`except`块里的任何代码。

```python
def test():
    try:
        # 因为finally块中包含了return语句
        # 所以下面的return语句失去作用
        return True
    finally:
        return False
a = test()
print(a)#False
```



### `raise`引发异常

如果需要在程序自行引发异常，则应使用`raise`语句。`raise`语句有如下三种用法：

- raise：单独一个raise。该语句引发当前上下文中捕获的异常(比如在`except`块中)，或默认引发`RuntimeError`异常。
- raise异常类：raise后带一个异常类。该语句引发指定异常类的默认实例。
- raise异常对象：引发指定的异常对象。

上面三种用法最终都是要引发一个异常实例(即使指定的是异常类，实际上也是引发该类的默认实例)，raise每次只能引发一个异常实例。



当Python解释器接收到开发者自行引发的异常时，同样会中止当前的执行流，跳到该异常对应的`except`块，由该`except`块来处理该异常。

```python
import traceback
def main():
    try:
        # 使用try...except来捕捉异常
        # 此时即使程序出现异常，也不会传播给main函数
        mtd(3)
    except Exception as e:
        print('程序出现异常:', e)
    # 不使用try...except捕捉异常，异常会传播出来导致程序中止
    mtd(3)
def mtd(a):
    if a > 0:
        #当打印异常对象时,内容为"a的值大于0，不符合要求"
        #这段字符串是对异常对象的描述
        raise ValueError("a的值大于0，不符合要求")
main()
```



### `except`和`raise`同时使用

当一个异常出现时，单靠某个方法无法完全处理该异常，必须由几个方法协作才可完全处理该异常。也就是说在异常出现的当前方法中，程序只对异常进行部分处理，还有些处理需要在该方法的调用者中才能完成，所以应该再次引发异常，让该方法的调用者也能捕获到异常。

```python
class AuctionException(Exception): pass
class AuctionTest:
    def __init__(self, init_price):
        self.init_price = init_price
    def bid(self, bid_price):
        d = 0.0
        try:
            d = float(bid_price)
        except Exception as e:
            # 此处只是简单地打印异常信息
            print("转换出异常：", e)
            # 再次引发自定义异常
            #异常包装
            raise AuctionException(e) 
        if self.init_price > d:
            raise AuctionException("竞拍价比起拍价低，不允许竞拍！")
        initPrice = d
def main():
    at = AuctionTest(20.4)
    try:
        at.bid("df")
    except AuctionException as ae: #AuctionException as ae:
        # 再次捕获到bid()方法中的异常，并对该异常进行处理
        print('main函数捕捉的异常：', ae)
main()
```

如果程序需要将原始异常的详细信息直接传播出去，Python也允许用自定义异常对原始异常进行包装`raise AuctionException(e)`，将原始异常`e`包装成了`AuctionException`异常，这种方式被称为异常包装或异常转译。



### Python的异常传播轨迹

当应用程序运行时，经常会发生一系列函数或方法调用，从而形成"函数调用栈"。异常的传播则相反：只要异常没有被完全捕获(包括异常没有被捕获，或者异常被处理后重新引发了新异常)，异常就从发生异常的函数或方法逐渐向外传播，首先传给该函数或方法的调用者，该函数或方法的调用者再传给其调用者······直至最后传到Python解释器，此时Python解释器会中止该程序，并打印异常的传播轨迹信息。

`traceback`模块来处理异常传播轨迹，使用`traceback`可以方便地处理Python的异常传播轨迹

- `traceback.print_exc()`：将异常传播轨迹信息输出到控制台或指定文件中。

```python
# 导入trackback模块
import traceback
class SelfException(Exception): pass

def main():
    firstMethod()
def firstMethod():
    secondMethod()
def secondMethod():
    thirdMethod()
def thirdMethod():
    raise SelfException("自定义异常信息")
try:
    main()
except:
    # 捕捉异常，并将异常传播信息输出控制台
    traceback.print_exc()
    # 捕捉异常，并将异常传播信息输出指定文件中
    # traceback.print_exc(file=open('log.txt', 'a'))
```



### 异常处理原则

- 不要过度使用异常。异常处理机制的初衷是将不可预期异常的处理代码和正常的业务逻辑代码分离。异常机制的效率比正常的流程控制效率差，不要使用异常处理来代替正常程序流程控制。
- 不要使用过于庞大的`try`块
- 不要忽略捕获到的异常

